<sdf version='1.9'>
  <model name='physics'>
    <link name='base_link'>
      <inertial>
        <pose>0 0 0 0 0 0</pose>
        <mass>2.3999999999999999</mass>
        <inertia>
          <ixx>5.0489999999999986</ixx>
          <ixy>0</ixy>
          <ixz>0</ixz>
          <iyy>5.016</iyy>
          <iyz>0</iyz>
          <izz>5.0650000000000013</izz>
        </inertia>
      </inertial>
      <collision name='base_link_collision'>
        <pose>0 0 0 0 0 0</pose>
        <geometry>
          <box>
            <size>0.20000000000000001 0.69999999999999996 0.10000000000000001</size>
          </box>
        </geometry>
      </collision>
      <collision name='base_link_fixed_joint_lump__wing_backward_left_collision_1'>
        <pose>0.20000000000000001 -0.34999999999999998 0 0 0 0</pose>
        <geometry>
          <box>
            <size>0.20000000000000001 0.69999999999999996 0.10000000000000001</size>
          </box>
        </geometry>
      </collision>
      <collision name='base_link_fixed_joint_lump__wing_backward_right_collision_2'>
        <pose>-0.20000000000000001 -0.34999999999999998 0 0 0 0</pose>
        <geometry>
          <box>
            <size>0.20000000000000001 0.69999999999999996 0.10000000000000001</size>
          </box>
        </geometry>
      </collision>
      <collision name='base_link_fixed_joint_lump__wing_forward_left_collision_3'>
        <pose>0.20000000000000001 0.34999999999999998 0 0 0 0</pose>
        <geometry>
          <box>
            <size>0.20000000000000001 0.69999999999999996 0.10000000000000001</size>
          </box>
        </geometry>
      </collision>
      <collision name='base_link_fixed_joint_lump__wing_forward_right_collision_4'>
        <pose>-0.20000000000000001 0.34999999999999998 0 0 0 0</pose>
        <geometry>
          <box>
            <size>0.20000000000000001 0.69999999999999996 0.10000000000000001</size>
          </box>
        </geometry>
      </collision>
      <visual name='base_link_visual'>
        <pose>0 0 0 0 0 0</pose>
        <geometry>
          <box>
            <size>0.20000000000000001 0.69999999999999996 0.10000000000000001</size>
          </box>
        </geometry>
        <material>
          <diffuse>1 1 1 1</diffuse>
          <ambient>1 1 1 1</ambient>
        </material>
      </visual>
      <visual name='base_link_fixed_joint_lump__wing_backward_left_visual_1'>
        <pose>0.20000000000000001 -0.34999999999999998 0 0 0 -2.358185307179586</pose>
        <geometry>
          <box>
            <size>0.20000000000000001 0.69999999999999996 0.10000000000000001</size>
          </box>
        </geometry>
        <material>
          <diffuse>1 1 1 1</diffuse>
          <ambient>1 1 1 1</ambient>
        </material>
      </visual>
      <visual name='base_link_fixed_joint_lump__wing_backward_right_visual_2'>
        <pose>-0.20000000000000001 -0.34999999999999998 0 0 0 2.355</pose>
        <geometry>
          <box>
            <size>0.20000000000000001 0.69999999999999996 0.10000000000000001</size>
          </box>
        </geometry>
        <material>
          <diffuse>1 1 1 1</diffuse>
          <ambient>1 1 1 1</ambient>
        </material>
      </visual>
      <visual name='base_link_fixed_joint_lump__wing_forward_left_visual_3'>
        <pose>0.20000000000000001 0.34999999999999998 0 0 0 -0.78818530717958624</pose>
        <geometry>
          <box>
            <size>0.20000000000000001 0.69999999999999996 0.10000000000000001</size>
          </box>
        </geometry>
        <material>
          <diffuse>1 1 1 1</diffuse>
          <ambient>1 1 1 1</ambient>
        </material>
      </visual>
      <visual name='base_link_fixed_joint_lump__wing_forward_right_visual_4'>
        <pose>-0.20000000000000001 0.34999999999999998 0 0 0 0.78500000000000025</pose>
        <geometry>
          <box>
            <size>0.20000000000000001 0.69999999999999996 0.10000000000000001</size>
          </box>
        </geometry>
        <material>
          <diffuse>1 1 1 1</diffuse>
          <ambient>1 1 1 1</ambient>
        </material>
      </visual>
    </link>
    <joint name='propeller_backward_left_joint' type='revolute'>
      <pose relative_to='base_link'>0.40000000000000002 -0.52499999999999991 0.050000000000000003 0 0 0</pose>
      <parent>base_link</parent>
      <child>propeller_backward_left</child>
      <axis>
        <xyz>0 0 1</xyz>
        <limit>
          <lower>-inf</lower>
          <upper>inf</upper>
        </limit>
        <dynamics>
          <spring_reference>0</spring_reference>
          <spring_stiffness>0</spring_stiffness>
        </dynamics>
      </axis>
    </joint>
    <link name='propeller_backward_left'>
      <pose relative_to='propeller_backward_left_joint'>0 0 0 0 0 0</pose>
      <inertial>
        <pose>0 0 0 0 0 0</pose>
        <mass>0.01</mass>
        <inertia>
          <ixx>1</ixx>
          <ixy>0</ixy>
          <ixz>0</ixz>
          <iyy>1</iyy>
          <iyz>0</iyz>
          <izz>1</izz>
        </inertia>
      </inertial>
      <collision name='propeller_backward_left_collision'>
        <pose>0 0 0 0 0 0</pose>
        <geometry>
          <box>
            <size>0.050000000000000003 0.59999999999999998 0.01</size>
          </box>
        </geometry>
      </collision>
      <visual name='propeller_backward_left_visual'>
        <pose>0 0 0 3.1415926535897931 0.52492598692312675 3.1415926535897931</pose>
        <geometry>
          <box>
            <size>0.050000000000000003 0.59999999999999998 0.01</size>
          </box>
        </geometry>
        <material>
          <diffuse>0 0 1 1</diffuse>
          <ambient>0 0 1 1</ambient>
        </material>
      </visual>
    </link>
    <joint name='wheel_backward_left_joint' type='revolute'>
      <pose relative_to='base_link'>0.40000000000000002 -0.52499999999999991 -0.070000000000000007 0 0 0</pose>
      <parent>base_link</parent>
      <child>wheel_backward_left</child>
      <axis>
        <xyz>0 0 1</xyz>
        <limit>
          <lower>-inf</lower>
          <upper>inf</upper>
        </limit>
        <dynamics>
          <spring_reference>0</spring_reference>
          <spring_stiffness>0</spring_stiffness>
        </dynamics>
      </axis>
    </joint>
    <link name='wheel_backward_left'>
      <pose relative_to='wheel_backward_left_joint'>0 0 0 0 0 0</pose>
      <inertial>
        <pose>0 0 0 0 0 0</pose>
        <mass>0.01</mass>
        <inertia>
          <ixx>1</ixx>
          <ixy>0</ixy>
          <ixz>0</ixz>
          <iyy>1</iyy>
          <iyz>0</iyz>
          <izz>1</izz>
        </inertia>
      </inertial>
      <collision name='wheel_backward_left_collision'>
        <pose>0 0 0 0 0 0</pose>
        <geometry>
          <cylinder>
            <length>0.080000000000000002</length>
            <radius>0.10000000000000001</radius>
          </cylinder>
        </geometry>
      </collision>
      <visual name='wheel_backward_left_visual'>
        <pose>0 0 0 0 1.5707963267948966 0</pose>
        <geometry>
          <cylinder>
            <length>0.080000000000000002</length>
            <radius>0.10000000000000001</radius>
          </cylinder>
        </geometry>
        <material>
          <diffuse>0 0 0 1</diffuse>
          <ambient>0 0 0 1</ambient>
        </material>
      </visual>
    </link>
    <joint name='propeller_backward_right_joint' type='revolute'>
      <pose relative_to='base_link'>-0.40000000000000002 -0.52499999999999991 0.050000000000000003 0 0 0</pose>
      <parent>base_link</parent>
      <child>propeller_backward_right</child>
      <axis>
        <xyz>0 0 1</xyz>
        <limit>
          <lower>-inf</lower>
          <upper>inf</upper>
        </limit>
        <dynamics>
          <spring_reference>0</spring_reference>
          <spring_stiffness>0</spring_stiffness>
        </dynamics>
      </axis>
    </joint>
    <link name='propeller_backward_right'>
      <pose relative_to='propeller_backward_right_joint'>0 0 0 0 0 0</pose>
      <inertial>
        <pose>0 0 0 0 0 0</pose>
        <mass>0.01</mass>
        <inertia>
          <ixx>1</ixx>
          <ixy>0</ixy>
          <ixz>0</ixz>
          <iyy>1</iyy>
          <iyz>0</iyz>
          <izz>1</izz>
        </inertia>
      </inertial>
      <collision name='propeller_backward_right_collision'>
        <pose>0 0 0 0 0 0</pose>
        <geometry>
          <box>
            <size>0.050000000000000003 0.59999999999999998 0.01</size>
          </box>
        </geometry>
      </collision>
      <visual name='propeller_backward_right_visual'>
        <pose>0 0 0 0 0.52333333333333332 0</pose>
        <geometry>
          <box>
            <size>0.050000000000000003 0.59999999999999998 0.01</size>
          </box>
        </geometry>
        <material>
          <diffuse>0 0 1 1</diffuse>
          <ambient>0 0 1 1</ambient>
        </material>
      </visual>
    </link>
    <joint name='wheel_backward_right_joint' type='revolute'>
      <pose relative_to='base_link'>-0.40000000000000002 -0.52499999999999991 -0.070000000000000007 0 0 0</pose>
      <parent>base_link</parent>
      <child>wheel_backward_right</child>
      <axis>
        <xyz>0 0 1</xyz>
        <limit>
          <lower>-inf</lower>
          <upper>inf</upper>
        </limit>
        <dynamics>
          <spring_reference>0</spring_reference>
          <spring_stiffness>0</spring_stiffness>
        </dynamics>
      </axis>
    </joint>
    <link name='wheel_backward_right'>
      <pose relative_to='wheel_backward_right_joint'>0 0 0 0 0 0</pose>
      <inertial>
        <pose>0 0 0 0 0 0</pose>
        <mass>0.01</mass>
        <inertia>
          <ixx>1</ixx>
          <ixy>0</ixy>
          <ixz>0</ixz>
          <iyy>1</iyy>
          <iyz>0</iyz>
          <izz>1</izz>
        </inertia>
      </inertial>
      <collision name='wheel_backward_right_collision'>
        <pose>0 0 0 0 0 0</pose>
        <geometry>
          <cylinder>
            <length>0.080000000000000002</length>
            <radius>0.10000000000000001</radius>
          </cylinder>
        </geometry>
      </collision>
      <visual name='wheel_backward_right_visual'>
        <pose>0 0 0 0 1.5707963267948966 0</pose>
        <geometry>
          <cylinder>
            <length>0.080000000000000002</length>
            <radius>0.10000000000000001</radius>
          </cylinder>
        </geometry>
        <material>
          <diffuse>0 0 0 1</diffuse>
          <ambient>0 0 0 1</ambient>
        </material>
      </visual>
    </link>
    <joint name='propeller_forward_left_joint' type='revolute'>
      <pose relative_to='base_link'>0.40000000000000002 0.52499999999999991 0.050000000000000003 0 0 0</pose>
      <parent>base_link</parent>
      <child>propeller_forward_left</child>
      <axis>
        <xyz>0 0 1</xyz>
        <limit>
          <lower>-inf</lower>
          <upper>inf</upper>
        </limit>
        <dynamics>
          <spring_reference>0</spring_reference>
          <spring_stiffness>0</spring_stiffness>
        </dynamics>
      </axis>
    </joint>
    <link name='propeller_forward_left'>
      <pose relative_to='propeller_forward_left_joint'>0 0 0 0 0 0</pose>
      <inertial>
        <pose>0 0 0 0 0 0</pose>
        <mass>0.01</mass>
        <inertia>
          <ixx>1</ixx>
          <ixy>0</ixy>
          <ixz>0</ixz>
          <iyy>1</iyy>
          <iyz>0</iyz>
          <izz>1</izz>
        </inertia>
      </inertial>
      <collision name='propeller_forward_left_collision'>
        <pose>0 0 0 0 0 0</pose>
        <geometry>
          <box>
            <size>0.050000000000000003 0.59999999999999998 0.01</size>
          </box>
        </geometry>
      </collision>
      <visual name='propeller_forward_left_visual'>
        <pose>0 0 0 3.1415926535897931 0.52492598692312675 3.1415926535897931</pose>
        <geometry>
          <box>
            <size>0.050000000000000003 0.59999999999999998 0.01</size>
          </box>
        </geometry>
        <material>
          <diffuse>0 0 1 1</diffuse>
          <ambient>0 0 1 1</ambient>
        </material>
      </visual>
    </link>
    <joint name='wheel_forward_left_joint' type='revolute'>
      <pose relative_to='base_link'>0.40000000000000002 0.52499999999999991 -0.070000000000000007 0 0 0</pose>
      <parent>base_link</parent>
      <child>wheel_forward_left</child>
      <axis>
        <xyz>0 0 1</xyz>
        <limit>
          <lower>-inf</lower>
          <upper>inf</upper>
        </limit>
        <dynamics>
          <spring_reference>0</spring_reference>
          <spring_stiffness>0</spring_stiffness>
        </dynamics>
      </axis>
    </joint>
    <link name='wheel_forward_left'>
      <pose relative_to='wheel_forward_left_joint'>0 0 0 0 0 0</pose>
      <inertial>
        <pose>0 0 0 0 0 0</pose>
        <mass>0.01</mass>
        <inertia>
          <ixx>1</ixx>
          <ixy>0</ixy>
          <ixz>0</ixz>
          <iyy>1</iyy>
          <iyz>0</iyz>
          <izz>1</izz>
        </inertia>
      </inertial>
      <collision name='wheel_forward_left_collision'>
        <pose>0 0 0 0 0 0</pose>
        <geometry>
          <cylinder>
            <length>0.080000000000000002</length>
            <radius>0.10000000000000001</radius>
          </cylinder>
        </geometry>
      </collision>
      <visual name='wheel_forward_left_visual'>
        <pose>0 0 0 0 1.5707963267948966 0</pose>
        <geometry>
          <cylinder>
            <length>0.080000000000000002</length>
            <radius>0.10000000000000001</radius>
          </cylinder>
        </geometry>
        <material>
          <diffuse>0 0 0 1</diffuse>
          <ambient>0 0 0 1</ambient>
        </material>
      </visual>
    </link>
    <joint name='propeller_forward_right_joint' type='revolute'>
      <pose relative_to='base_link'>-0.40000000000000002 0.52499999999999991 0.050000000000000003 0 0 0</pose>
      <parent>base_link</parent>
      <child>propeller_forward_right</child>
      <axis>
        <xyz>0 0 1</xyz>
        <limit>
          <lower>-inf</lower>
          <upper>inf</upper>
        </limit>
        <dynamics>
          <spring_reference>0</spring_reference>
          <spring_stiffness>0</spring_stiffness>
        </dynamics>
      </axis>
    </joint>
    <link name='propeller_forward_right'>
      <pose relative_to='propeller_forward_right_joint'>0 0 0 0 0 0</pose>
      <inertial>
        <pose>0 0 0 0 0 0</pose>
        <mass>0.01</mass>
        <inertia>
          <ixx>1</ixx>
          <ixy>0</ixy>
          <ixz>0</ixz>
          <iyy>1</iyy>
          <iyz>0</iyz>
          <izz>1</izz>
        </inertia>
      </inertial>
      <collision name='propeller_forward_right_collision'>
        <pose>0 0 0 0 0 0</pose>
        <geometry>
          <box>
            <size>0.050000000000000003 0.59999999999999998 0.01</size>
          </box>
        </geometry>
      </collision>
      <visual name='propeller_forward_right_visual'>
        <pose>0 0 0 0 0.52333333333333332 0</pose>
        <geometry>
          <box>
            <size>0.050000000000000003 0.59999999999999998 0.01</size>
          </box>
        </geometry>
        <material>
          <diffuse>0 0 1 1</diffuse>
          <ambient>0 0 1 1</ambient>
        </material>
      </visual>
    </link>
    <joint name='wheel_forward_right_joint' type='revolute'>
      <pose relative_to='base_link'>-0.40000000000000002 0.52499999999999991 -0.070000000000000007 0 0 0</pose>
      <parent>base_link</parent>
      <child>wheel_forward_right</child>
      <axis>
        <xyz>0 0 1</xyz>
        <limit>
          <lower>-inf</lower>
          <upper>inf</upper>
        </limit>
        <dynamics>
          <spring_reference>0</spring_reference>
          <spring_stiffness>0</spring_stiffness>
        </dynamics>
      </axis>
    </joint>
    <link name='wheel_forward_right'>
      <pose relative_to='wheel_forward_right_joint'>0 0 0 0 0 0</pose>
      <inertial>
        <pose>0 0 0 0 0 0</pose>
        <mass>0.01</mass>
        <inertia>
          <ixx>1</ixx>
          <ixy>0</ixy>
          <ixz>0</ixz>
          <iyy>1</iyy>
          <iyz>0</iyz>
          <izz>1</izz>
        </inertia>
      </inertial>
      <collision name='wheel_forward_right_collision'>
        <pose>0 0 0 0 0 0</pose>
        <geometry>
          <cylinder>
            <length>0.080000000000000002</length>
            <radius>0.10000000000000001</radius>
          </cylinder>
        </geometry>
      </collision>
      <visual name='wheel_forward_right_visual'>
        <pose>0 0 0 0 1.5707963267948966 0</pose>
        <geometry>
          <cylinder>
            <length>0.080000000000000002</length>
            <radius>0.10000000000000001</radius>
          </cylinder>
        </geometry>
        <material>
          <diffuse>0 0 0 1</diffuse>
          <ambient>0 0 0 1</ambient>
        </material>
      </visual>
    </link>
    <frame name='wing_backward_left_joint' attached_to='base_link'>
      <pose>0.20000000000000001 -0.34999999999999998 0 0 0 0</pose>
    </frame>
    <frame name='wing_backward_left' attached_to='wing_backward_left_joint'>
      <pose>0 0 0 0 0 0</pose>
    </frame>
    <frame name='wing_backward_right_joint' attached_to='base_link'>
      <pose>-0.20000000000000001 -0.34999999999999998 0 0 0 0</pose>
    </frame>
    <frame name='wing_backward_right' attached_to='wing_backward_right_joint'>
      <pose>0 0 0 0 0 0</pose>
    </frame>
    <frame name='wing_forward_left_joint' attached_to='base_link'>
      <pose>0.20000000000000001 0.34999999999999998 0 0 0 0</pose>
    </frame>
    <frame name='wing_forward_left' attached_to='wing_forward_left_joint'>
      <pose>0 0 0 0 0 0</pose>
    </frame>
    <frame name='wing_forward_right_joint' attached_to='base_link'>
      <pose>-0.20000000000000001 0.34999999999999998 0 0 0 0</pose>
    </frame>
    <frame name='wing_forward_right' attached_to='wing_forward_right_joint'>
      <pose>0 0 0 0 0 0</pose>
    </frame>
  </model>
</sdf>
